Workbook

Sheet Versão
A2: Contagem de Pontos de Função de Projetos
B4: Identificação da Demanda | C4: < Informar o nome da aplicação e Solicitação de Serviço a que se refere a contagem >
A6: Histórico deste documento
A7: Data | B7: Versão | C7: Autor | D7: Revisor | E7: Aprovado Por | F7: Descrição
A19: Insumos utilizados na Contagem
A20: Data | B20: Versão | C20: Descrição (Nome artefato / Nome e Link da REVISÃO FORMAL)
A32: Parecer do Estimador

Sheet Sumário
A1: Identificação da Demanda
A3: Roteiro de Métricas: | E3: Versão Pontua: | G3: 6.1.0 | H3: 9999 | I3: V36
A5: Demanda: | B5: =Versão!C4 -> < Informar o nome da aplicação e Solicitação de Serviço a que se refere a contagem >
A7: Linguagem: | E7: Responsável:
A9: Banco de Dados: | E9: Processo adotado:
A11: Plataforma: | E11: Tipo da Demanda:
A13: Tipo da Contagem: | E13: Método de Contagem:
A15: Propósito e Escopo da Contagem: | B15: < Descrever qual o propósito da contagem (por exemplo, (i) fornecer uma contagem de PF como insumo para o processo de estimativas de prazos e esforços para o desenvolvimento da aplicação; (ii) fornecer uma contagem de PF da base instalada de aplicações) >
A20: Fronteira/Aplicação:
A22: Contagem no PONTUA:
A27: Observações:
A33: Resumo da contagem de pontos de função
D35: Quantidade | G35: Total de PF
D36: Baixa | E36: Média | F36: Alta | G36: Baixa | H36: Média | I36: Alta
A37: ALI Arquivo Lógico Interno | B37: Função de Dados | D37: =ALI!E43 -> 0 | E37: =ALI!E44 -> 0 | F37: =ALI!E45 -> 0 | G37: =ALI!I43 -> 0 | H37: =ALI!I44 -> 0 | I37: =ALI!I45 -> 0
B38: Retrabalho | D38: =ALI!E48 -> 0 | E38: =ALI!E49 -> 0 | F38: =ALI!E50 -> 0 | G38: =ALI!I48 -> 0 | H38: =ALI!I49 -> 0 | I38: =ALI!I50 -> 0
B39: Total de ALI | D39: =D37+D38 -> 0 | E39: =E37+E38 -> 0 | F39: =F37+F38 -> 0 | G39: =G37+G38 -> 0 | H39: =H37+H38 -> 0 | I39: =I37+I38 -> 0
A40: AIE Arquivo de Interface Externa | B40: Função de Dados | D40: =AIE!E43 -> 0 | E40: =AIE!E44 -> 0 | F40: =AIE!E45 -> 0 | G40: =AIE!I43 -> 0 | H40: =AIE!I44 -> 0 | I40: =AIE!I45 -> 0
B41: Retrabalho | D41: =AIE!E48 -> 0 | E41: =AIE!E49 -> 0 | F41: =AIE!E50 -> 0 | G41: =AIE!I48 -> 0 | H41: =AIE!I49 -> 0 | I41: =AIE!I50 -> 0
B42: Total de AIE | D42: =D40+D41 -> 0 | E42: =E40+E41 -> 0 | F42: =F40+F41 -> 0 | G42: =G40+G41 -> 0 | H42: =H40+H41 -> 0 | I42: =I40+I41 -> 0
A43: EE Entrada Externa | B43: Função Transacional | D43: =EE!E43 -> 0 | E43: =EE!E44 -> 0 | F43: =EE!E45 -> 0 | G43: =EE!I43 -> 0 | H43: =EE!I44 -> 0 | I43: =EE!I45 -> 0
B44: Retrabalho | D44: =EE!E48 -> 0 | E44: =EE!E49 -> 0 | F44: =EE!E50 -> 0 | G44: =EE!I48 -> 0 | H44: =EE!I49 -> 0 | I44: =EE!I50 -> 0
B45: Total de EE | D45: =D43+D44 -> 0 | E45: =E43+E44 -> 0 | F45: =F43+F44 -> 0 | G45: =G43+G44 -> 0 | H45: =H43+H44 -> 0 | I45: =I43+I44 -> 0
A46: SE Saída Externa | B46: Função Transacional | D46: =SE!E43 -> 0 | E46: =SE!E44 -> 0 | F46: =SE!E45 -> 0 | G46: =SE!I43 -> 0 | H46: =SE!I44 -> 0 | I46: =SE!I45 -> 0
B47: Retrabalho | D47: =SE!E48 -> 0 | E47: =SE!E49 -> 0 | F47: =SE!E50 -> 0 | G47: =SE!I48 -> 0 | H47: =SE!I49 -> 0 | I47: =SE!I50 -> 0
B48: Total de SE | D48: =D46+D47 -> 0 | E48: =E46+E47 -> 0 | F48: =F46+F47 -> 0 | G48: =G46+G47 -> 0 | H48: =H46+H47 -> 0 | I48: =I46+I47 -> 0
A49: CE Consulta Externa | B49: Função Transacional | D49: =CE!E43 -> 0 | E49: =CE!E44 -> 0 | F49: =CE!E45 -> 0 | G49: =CE!I43 -> 0 | H49: =CE!I44 -> 0 | I49: =CE!I45 -> 0
B50: Retrabalho | D50: =CE!E48 -> 0 | E50: =CE!E49 -> 0 | F50: =CE!E50 -> 0 | G50: =CE!I48 -> 0 | H50: =CE!I49 -> 0 | I50: =CE!I50 -> 0
B51: Total de CE | D51: =D49+D50 -> 0 | E51: =E49+E50 -> 0 | F51: =F49+F50 -> 0 | G51: =G49+G50 -> 0 | H51: =H49+H50 -> 0 | I51: =I49+I50 -> 0
H53: PF Função de Dados | I53: =SUM(G37:I37,G40:I40) -> 0
H54: PF Retrabalho | I54: =SUM(G38:I38,G41:I41,G44:I44,G47:I47,G50:I50) -> 0
H55: PF Função Transacional | I55: =SUM(G43:I43,G46:I46,G49:I49) -> 0
H56: Total de PF Bruto | I56: =I53+I54+I55 -> 0
A58: Sim | B58: Não
A60: ¹Scope Creep: | C60: Não | E60: Percentual: | F60: =IF(C60="Sim",0.35,0) -> 0 | H60: =IF(C60="Sim",($I$56-$I$54)*F60,0) -> 0
A62: Help: | C62: Não | E62: Percentual: | F62: 0.05 | H62: =IF(C62="Não",0,(EE!AF40+SE!AF40+CE!AF40-EE!K59-CE!K59-SE!K59)*F62) -> 0
A64: GRS: | C64: Não | E64: Percentual: | F64: 0.02 | H64: =IF(C64="Sim",(I56-I54-EE!K60-EE!K61-SE!K60-CE!K60)*F64,0) -> 0
A66: Testes Não Funcionais: | C66: Não | E66: Percentual: | F66: 0.25 | H66: =IF(C66="Sim",(EE!AF40+SE!AF40+CE!AF40-EE!K59-CE!K59-SE!K59)*F66,0) -> 0
A68: Roteiro de Homologação: | C68: Não | E68: Percentual: | F68: 0.02 | H68: =IF(C68="Sim",(G45+H45+I45+G48+H48+I48+G51+H51+I51-EE!K60-EE!K61-CE!K60-SE!K60)*F68,0) -> 0
A70: ² Fator de Criticidade: | C70: Não | E70: Percentual: | F70: =IF(AND(I56<100,C70="Sim"),0.35,0) -> 0 | H70: =IF(C70="Sim",(I56+H60+H62+H64+H66+H68)*F70,0) -> 0
...

Sheet ALI
B2: Identificação da Demanda: | E2: =Versão!C4 -> < Informar o nome da aplicação e Solicitação de Serviço a que se refere a contagem >
B9: Formulário de Identificação de Arquivos Lógicos Internos (ALI)
B11: Orientações
B12: Evite editar os dados apresentados, cadastrar novas funcionalidades e/ou alterar seus dados. Esta planilha não realiza cálculos nas funções. Os dados da função foram exportados do Pontua, inclusive a Complexidade e o PF. O valor do PF foi calculado conforme Roteiro de Métricas informado na Contagem cadastrada na aplicação. Do Item de Roteiro é feita a equivalência para Tipo de Demanda e Classificação.
B13: ¹ Em caso de cópia de Tipo de Demanda e/ou Classificação – colar o conteúdo em modo texto puro pois as células possuem fórmulas (menu “Editar” - “Colar Especial...” - “Texto”)
B14: Caso seja necessário transfira o conteúdo para a planilha do respectivo cliente. As planilhas podem ser obtidas na página do Escritório de Métricas:
B15: https://gitcorporativo.serpro/supde/SUPDE-EMPF/wikis/home
B17: Nome do ALI | E17: RL | G17: Memória RL | I17: TD's | K17: Memória TD | M17: Tipo de Demanda ¹ | O17: Classificação | Y17: Compl | AE17: PF | AF17: PF Cheio | AK17: Rastreabilidade / Justificativa / Motivo-Comentário | AN17: Marcadores de Grupo
M19: =IF(ISBLANK(AM19),'Item-Roteiro_PONTUA'!$B$20,VLOOKUP(AM19,'Item-Roteiro_PONTUA'!$A$2:$C$86,2,0)) -> Desenvolvimento | O19: =IF(ISBLANK(AM19),'Item-Roteiro_PONTUA'!$C$20,VLOOKUP(AM19,'Item-Roteiro_PONTUA'!$A$2:$C$86,3,0)) -> Incluída | AF19: =IF(Y19="Baixa",7,IF(Y19="Média",10,IF(Y19="Alta",15,"*"))) -> *
M20: =IF(ISBLANK(AM20),'Item-Roteiro_PONTUA'!$B$20,VLOOKUP(AM20,'Item-Roteiro_PONTUA'!$A$2:$C$86,2,0)) -> Desenvolvimento | O20: =IF(ISBLANK(AM20),'Item-Roteiro_PONTUA'!$C$20,VLOOKUP(AM20,'Item-Roteiro_PONTUA'!$A$2:$C$86,3,0)) -> Incluída
M21: =IF(ISBLANK(AM21),'Item-Roteiro_PONTUA'!$B$20,VLOOKUP(AM21,'Item-Roteiro_PONTUA'!$A$2:$C$86,2,0)) -> Desenvolvimento | O21: =IF(ISBLANK(AM21),'Item-Roteiro_PONTUA'!$C$20,VLOOKUP(AM21,'Item-Roteiro_PONTUA'!$A$2:$C$86,3,0)) -> Incluída
M22: =IF(ISBLANK(AM22),'Item-Roteiro_PONTUA'!$B$20,VLOOKUP(AM22,'Item-Roteiro_PONTUA'!$A$2:$C$86,2,0)) -> Desenvolvimento | O22: =IF(ISBLANK(AM22),'Item-Roteiro_PONTUA'!$C$20,VLOOKUP(AM22,'Item-Roteiro_PONTUA'!$A$2:$C$86,3,0)) -> Incluída
M23: =IF(ISBLANK(AM23),'Item-Roteiro_PONTUA'!$B$20,VLOOKUP(AM23,'Item-Roteiro_PONTUA'!$A$2:$C$86,2,0)) -> Desenvolvimento | O23: =IF(ISBLANK(AM23),'Item-Roteiro_PONTUA'!$C$20,VLOOKUP(AM23,'Item-Roteiro_PONTUA'!$A$2:$C$86,3,0)) -> Incluída
M24: =IF(ISBLANK(AM24),'Item-Roteiro_PONTUA'!$B$20,VLOOKUP(AM24,'Item-Roteiro_PONTUA'!$A$2:$C$86,2,0)) -> Desenvolvimento | O24: =IF(ISBLANK(AM24),'Item-Roteiro_PONTUA'!$C$20,VLOOKUP(AM24,'Item-Roteiro_PONTUA'!$A$2:$C$86,3,0)) -> Incluída
M25: =IF(ISBLANK(AM25),'Item-Roteiro_PONTUA'!$B$20,VLOOKUP(AM25,'Item-Roteiro_PONTUA'!$A$2:$C$86,2,0)) -> Desenvolvimento | O25: =IF(ISBLANK(AM25),'Item-Roteiro_PONTUA'!$C$20,VLOOKUP(AM25,'Item-Roteiro_PONTUA'!$A$2:$C$86,3,0)) -> Incluída
M26: =IF(ISBLANK(AM26),'Item-Roteiro_PONTUA'!$B$20,VLOOKUP(AM26,'Item-Roteiro_PONTUA'!$A$2:$C$86,2,0)) -> Desenvolvimento | O26: =IF(ISBLANK(AM26),'Item-Roteiro_PONTUA'!$C$20,VLOOKUP(AM26,'Item-Roteiro_PONTUA'!$A$2:$C$86,3,0)) -> Incluída
M27: =IF(ISBLANK(AM27),'Item-Roteiro_PONTUA'!$B$20,VLOOKUP(AM27,'Item-Roteiro_PONTUA'!$A$2:$C$86,2,0)) -> Desenvolvimento | O27: =IF(ISBLANK(AM27),'Item-Roteiro_PONTUA'!$C$20,VLOOKUP(AM27,'Item-Roteiro_PONTUA'!$A$2:$C$86,3,0)) -> Incluída
M28: =IF(ISBLANK(AM28),'Item-Roteiro_PONTUA'!$B$20,VLOOKUP(AM28,'Item-Roteiro_PONTUA'!$A$2:$C$86,2,0)) -> Desenvolvimento | O28: =IF(ISBLANK(AM28),'Item-Roteiro_PONTUA'!$C$20,VLOOKUP(AM28,'Item-Roteiro_PONTUA'!$A$2:$C$86,3,0)) -> Incluída
M29: =IF(ISBLANK(AM29),'Item-Roteiro_PONTUA'!$B$20,VLOOKUP(AM29,'Item-Roteiro_PONTUA'!$A$2:$C$86,2,0)) -> Desenvolvimento | O29: =IF(ISBLANK(AM29),'Item-Roteiro_PONTUA'!$C$20,VLOOKUP(AM29,'Item-Roteiro_PONTUA'!$A$2:$C$86,3,0)) -> Incluída
M30: =IF(ISBLANK(AM30),'Item-Roteiro_PONTUA'!$B$20,VLOOKUP(AM30,'Item-Roteiro_PONTUA'!$A$2:$C$86,2,0)) -> Desenvolvimento | O30: =IF(ISBLANK(AM30),'Item-Roteiro_PONTUA'!$C$20,VLOOKUP(AM30,'Item-Roteiro_PONTUA'!$A$2:$C$86,3,0)) -> Incluída
M31: =IF(ISBLANK(AM31),'Item-Roteiro_PONTUA'!$B$20,VLOOKUP(AM31,'Item-Roteiro_PONTUA'!$A$2:$C$86,2,0)) -> Desenvolvimento | O31: =IF(ISBLANK(AM31),'Item-Roteiro_PONTUA'!$C$20,VLOOKUP(AM31,'Item-Roteiro_PONTUA'!$A$2:$C$86,3,0)) -> Incluída
... M37: =IF(ISBLANK(AM37),'Item-Roteiro_PONTUA'!$B$20,VLOOKUP(AM37,'Item-Roteiro_PONTUA'!$A$2:$C$86,2,0)) -> Desenvolvimento | O37: =IF(ISBLANK(AM37),'Item-Roteiro_PONTUA'!$C$20,VLOOKUP(AM37,'Item-Roteiro_PONTUA'!$A$2:$C$86,3,0)) -> Incluída
M38: =IF(ISBLANK(AM38),'Item-Roteiro_PONTUA'!$B$20,VLOOKUP(AM38,'Item-Roteiro_PONTUA'!$A$2:$C$86,2,0)) -> Desenvolvimento | O38: =IF(ISBLANK(AM38),'Item-Roteiro_PONTUA'!$C$20,VLOOKUP(AM38,'Item-Roteiro_PONTUA'!$A$2:$C$86,3,0)) -> Incluída | AF38: =IF(Y38="Baixa",7,IF(Y38="Média",10,IF(Y38="Alta",15,"*"))) -> *
E41: Qtd de ALI | I41: Total de PF
C42: Complexidade | E42: Dados
C43: Baixa | E43: {=SUMPRODUCT((Y19:Y38=C43)*(LEFT(M19:M38,10)<>"Retrabalho"))} -> 0 | I43: {=SUMPRODUCT((Y19:Y38=C43)*(LEFT(M19:M38,10)<>"Retrabalho")*NOT(ISBLANK(AE19:AE38))*AE19:AE38)} -> 0
C44: Média | E44: {=SUMPRODUCT((Y19:Y38=C44)*(LEFT(M19:M38,10)<>"Retrabalho"))} -> 0 | I44: {=SUMPRODUCT((Y19:Y38=C44)*(LEFT(M19:M38,10)<>"Retrabalho")*NOT(ISBLANK(AE19:AE38))*AE19:AE38)} -> 0
C45: Alta | E45: {=SUMPRODUCT((Y19:Y38=C45)*(LEFT(M19:M38,10)<>"Retrabalho"))} -> 0 | I45: {=SUMPRODUCT((Y19:Y38=C45)*(LEFT(M19:M38,10)<>"Retrabalho")*NOT(ISBLANK(AE19:AE38))*AE19:AE38)} -> 0
E47: Retrabalho
C48: Baixa | E48: {=SUMPRODUCT((Y19:Y38=C48)*(LEFT(M19:M38,10)="Retrabalho"))} -> 0 | I48: {=SUMPRODUCT((Y19:Y38=C48)*(LEFT(M19:M38,10)="Retrabalho")*NOT(ISBLANK(AE19:AE38))*AE19:AE38)} -> 0
C49: Média | E49: {=SUMPRODUCT((Y19:Y38=C49)*(LEFT(M19:M38,10)="Retrabalho"))} -> 0 | I49: {=SUMPRODUCT((Y19:Y38=C49)*(LEFT(M19:M38,10)="Retrabalho")*NOT(ISBLANK(AE19:AE38))*AE19:AE38)} -> 0
C50: Alta | E50: {=SUMPRODUCT((Y19:Y38=C50)*(LEFT(M19:M38,10)="Retrabalho"))} -> 0 | I50: {=SUMPRODUCT((Y19:Y38=C50)*(LEFT(M19:M38,10)="Retrabalho")*NOT(ISBLANK(AE19:AE38))*AE19:AE38)} -> 0
E52: Total
C53: Baixa | E53: =E43+E48 -> 0 | I53: =I43+I48 -> 0
C54: Média | E54: =E44+E49 -> 0 | I54: =I44+I49 -> 0
C55: Alta | E55: =E45+E50 -> 0 | I55: =I45+I50 -> 0
E56: =E53+E54+E55 -> 0 | I56: =I53+I54+I55 -> 0

Sheet AIE
B2: Identificação da Demanda: | E2: ${demanda.nome}
B9: Formulário de Identificação de Arquivos Interface Externa (AIE)
B11: Orientações
B12: =ALI!B12 -> Evite editar os dados apresentados, cadastrar novas funcionalidades e/ou alterar seus dados. Esta planilha não realiza cálculos nas funções. Os dados da função foram exportados do Pontua, inclusive a Complexidade e o PF. O valor do PF foi calculado conforme Roteiro de Métricas informado na Contagem cadastrada na aplicação. Do Item de Roteiro é feita a equivalência para Tipo de Demanda e Classificação.
B13: =ALI!B13 -> ¹ Em caso de cópia de Tipo de Demanda e/ou Classificação – colar o conteúdo em modo texto puro pois as células possuem fórmulas (menu “Editar” - “Colar Especial...” - “Texto”)
B14: =ALI!B14 -> Caso seja necessário transfira o conteúdo para a planilha do respectivo cliente. As planilhas podem ser obtidas na página do Escritório de Métricas:
B15: =ALI!B15 -> https://gitcorporativo.serpro/supde/SUPDE-EMPF/wikis/home
B17: Nome do AIE | E17: RL | G17: Memória RL | I17: TD's | K17: Memória TD | M17: Tipo de Demanda ¹ | O17: Classificação | Y17: Compl | AE17: PF | AF17: PF Cheio | AK17: Rastreabilidade / Justificativa / Motivo-Comentário | AN17: Marcadores de Grupo
M19: =IF(ISBLANK(AM19),'Item-Roteiro_PONTUA'!$B$20,VLOOKUP(AM19,'Item-Roteiro_PONTUA'!$A$2:$C$86,2,0)) -> Desenvolvimento | O19: =IF(ISBLANK(AM19),'Item-Roteiro_PONTUA'!$C$20,VLOOKUP(AM19,'Item-Roteiro_PONTUA'!$A$2:$C$86,3,0)) -> Incluída | AF19: =IF(Y19="Baixa",7,IF(Y19="Média",10,IF(Y19="Alta",15,"*"))) -> *
M20: =IF(ISBLANK(AM20),'Item-Roteiro_PONTUA'!$B$20,VLOOKUP(AM20,'Item-Roteiro_PONTUA'!$A$2:$C$86,2,0)) -> Desenvolvimento | O20: =IF(ISBLANK(AM20),'Item-Roteiro_PONTUA'!$C$20,VLOOKUP(AM20,'Item-Roteiro_PONTUA'!$A$2:$C$86,3,0)) -> Incluída
M21: =IF(ISBLANK(AM21),'Item-Roteiro_PONTUA'!$B$20,VLOOKUP(AM21,'Item-Roteiro_PONTUA'!$A$2:$C$86,2,0)) -> Desenvolvimento | O21: =IF(ISBLANK(AM21),'Item-Roteiro_PONTUA'!$C$20,VLOOKUP(AM21,'Item-Roteiro_PONTUA'!$A$2:$C$86,3,0)) -> Incluída
M22: =IF(ISBLANK(AM22),'Item-Roteiro_PONTUA'!$B$20,VLOOKUP(AM22,'Item-Roteiro_PONTUA'!$A$2:$C$86,2,0)) -> Desenvolvimento | O22: =IF(ISBLANK(AM22),'Item-Roteiro_PONTUA'!$C$20,VLOOKUP(AM22,'Item-Roteiro_PONTUA'!$A$2:$C$86,3,0)) -> Incluída
M23: =IF(ISBLANK(AM23),'Item-Roteiro_PONTUA'!$B$20,VLOOKUP(AM23,'Item-Roteiro_PONTUA'!$A$2:$C$86,2,0)) -> Desenvolvimento | O23: =IF(ISBLANK(AM23),'Item-Roteiro_PONTUA'!$C$20,VLOOKUP(AM23,'Item-Roteiro_PONTUA'!$A$2:$C$86,3,0)) -> Incluída
M24: =IF(ISBLANK(AM24),'Item-Roteiro_PONTUA'!$B$20,VLOOKUP(AM24,'Item-Roteiro_PONTUA'!$A$2:$C$86,2,0)) -> Desenvolvimento | O24: =IF(ISBLANK(AM24),'Item-Roteiro_PONTUA'!$C$20,VLOOKUP(AM24,'Item-Roteiro_PONTUA'!$A$2:$C$86,3,0)) -> Incluída
M25: =IF(ISBLANK(AM25),'Item-Roteiro_PONTUA'!$B$20,VLOOKUP(AM25,'Item-Roteiro_PONTUA'!$A$2:$C$86,2,0)) -> Desenvolvimento | O25: =IF(ISBLANK(AM25),'Item-Roteiro_PONTUA'!$C$20,VLOOKUP(AM25,'Item-Roteiro_PONTUA'!$A$2:$C$86,3,0)) -> Incluída
M26: =IF(ISBLANK(AM26),'Item-Roteiro_PONTUA'!$B$20,VLOOKUP(AM26,'Item-Roteiro_PONTUA'!$A$2:$C$86,2,0)) -> Desenvolvimento | O26: =IF(ISBLANK(AM26),'Item-Roteiro_PONTUA'!$C$20,VLOOKUP(AM26,'Item-Roteiro_PONTUA'!$A$2:$C$86,3,0)) -> Incluída
M27: =IF(ISBLANK(AM27),'Item-Roteiro_PONTUA'!$B$20,VLOOKUP(AM27,'Item-Roteiro_PONTUA'!$A$2:$C$86,2,0)) -> Desenvolvimento | O27: =IF(ISBLANK(AM27),'Item-Roteiro_PONTUA'!$C$20,VLOOKUP(AM27,'Item-Roteiro_PONTUA'!$A$2:$C$86,3,0)) -> Incluída
M28: =IF(ISBLANK(AM28),'Item-Roteiro_PONTUA'!$B$20,VLOOKUP(AM28,'Item-Roteiro_PONTUA'!$A$2:$C$86,2,0)) -> Desenvolvimento | O28: =IF(ISBLANK(AM28),'Item-Roteiro_PONTUA'!$C$20,VLOOKUP(AM28,'Item-Roteiro_PONTUA'!$A$2:$C$86,3,0)) -> Incluída
M29: =IF(ISBLANK(AM29),'Item-Roteiro_PONTUA'!$B$20,VLOOKUP(AM29,'Item-Roteiro_PONTUA'!$A$2:$C$86,2,0)) -> Desenvolvimento | O29: =IF(ISBLANK(AM29),'Item-Roteiro_PONTUA'!$C$20,VLOOKUP(AM29,'Item-Roteiro_PONTUA'!$A$2:$C$86,3,0)) -> Incluída
M30: =IF(ISBLANK(AM30),'Item-Roteiro_PONTUA'!$B$20,VLOOKUP(AM30,'Item-Roteiro_PONTUA'!$A$2:$C$86,2,0)) -> Desenvolvimento | O30: =IF(ISBLANK(AM30),'Item-Roteiro_PONTUA'!$C$20,VLOOKUP(AM30,'Item-Roteiro_PONTUA'!$A$2:$C$86,3,0)) -> Incluída
M31: =IF(ISBLANK(AM31),'Item-Roteiro_PONTUA'!$B$20,VLOOKUP(AM31,'Item-Roteiro_PONTUA'!$A$2:$C$86,2,0)) -> Desenvolvimento | O31: =IF(ISBLANK(AM31),'Item-Roteiro_PONTUA'!$C$20,VLOOKUP(AM31,'Item-Roteiro_PONTUA'!$A$2:$C$86,3,0)) -> Incluída
... M37: =IF(ISBLANK(AM37),'Item-Roteiro_PONTUA'!$B$20,VLOOKUP(AM37,'Item-Roteiro_PONTUA'!$A$2:$C$86,2,0)) -> Desenvolvimento | O37: =IF(ISBLANK(AM37),'Item-Roteiro_PONTUA'!$C$20,VLOOKUP(AM37,'Item-Roteiro_PONTUA'!$A$2:$C$86,3,0)) -> Incluída
M38: =IF(ISBLANK(AM38),'Item-Roteiro_PONTUA'!$B$20,VLOOKUP(AM38,'Item-Roteiro_PONTUA'!$A$2:$C$86,2,0)) -> Desenvolvimento | O38: =IF(ISBLANK(AM38),'Item-Roteiro_PONTUA'!$C$20,VLOOKUP(AM38,'Item-Roteiro_PONTUA'!$A$2:$C$86,3,0)) -> Incluída | AF38: =IF(Y38="Baixa",7,IF(Y38="Média",10,IF(Y38="Alta",15,"*"))) -> *
E41: Qtd de AIE | I41: Total de PF
C42: Complexidade | E42: Dados
C43: Baixa | E43: {=SUMPRODUCT((Y19:Y38=C43)*(LEFT(M19:M38,10)<>"Retrabalho"))} -> 0 | I43: {=SUMPRODUCT((Y19:Y38=C43)*(LEFT(M19:M38,10)<>"Retrabalho")*NOT(ISBLANK(AE19:AE38))*AE19:AE38)} -> 0
C44: Média | E44: {=SUMPRODUCT((Y19:Y38=C44)*(LEFT(M19:M38,10)<>"Retrabalho"))} -> 0 | I44: {=SUMPRODUCT((Y19:Y38=C44)*(LEFT(M19:M38,10)<>"Retrabalho")*NOT(ISBLANK(AE19:AE38))*AE19:AE38)} -> 0
C45: Alta | E45: {=SUMPRODUCT((Y19:Y38=C45)*(LEFT(M19:M38,10)<>"Retrabalho"))} -> 0 | I45: {=SUMPRODUCT((Y19:Y38=C45)*(LEFT(M19:M38,10)<>"Retrabalho")*NOT(ISBLANK(AE19:AE38))*AE19:AE38)} -> 0
E47: Retrabalho
C48: Baixa | E48: {=SUMPRODUCT((Y19:Y38=C48)*(LEFT(M19:M38,10)="Retrabalho"))} -> 0 | I48: {=SUMPRODUCT((Y19:Y38=C48)*(LEFT(M19:M38,10)="Retrabalho")*NOT(ISBLANK(AE19:AE38))*AE19:AE38)} -> 0
C49: Média | E49: {=SUMPRODUCT((Y19:Y38=C49)*(LEFT(M19:M38,10)="Retrabalho"))} -> 0 | I49: {=SUMPRODUCT((Y19:Y38=C49)*(LEFT(M19:M38,10)="Retrabalho")*NOT(ISBLANK(AE19:AE38))*AE19:AE38)} -> 0
C50: Alta | E50: {=SUMPRODUCT((Y19:Y38=C50)*(LEFT(M19:M38,10)="Retrabalho"))} -> 0 | I50: {=SUMPRODUCT((Y19:Y38=C50)*(LEFT(M19:M38,10)="Retrabalho")*NOT(ISBLANK(AE19:AE38))*AE19:AE38)} -> 0
E52: Total
C53: Baixa | E53: =E43+E48 -> 0 | I53: =I43+I48 -> 0
C54: Média | E54: =E44+E49 -> 0 | I54: =I44+I49 -> 0
C55: Alta | E55: =E45+E50 -> 0 | I55: =I45+I50 -> 0
E56: =E53+E54+E55 -> 0 | I56: =I53+I54+I55 -> 0

Sheet EE
B2: Identificação da Demanda: | E2: ${demanda.nome}
B9: Formulário de Identificação de Entradas Externas (EE)
B11: Orientações
B12: =ALI!B12 -> Evite editar os dados apresentados, cadastrar novas funcionalidades e/ou alterar seus dados. Esta planilha não realiza cálculos nas funções. Os dados da função foram exportados do Pontua, inclusive a Complexidade e o PF. O valor do PF foi calculado conforme Roteiro de Métricas informado na Contagem cadastrada na aplicação. Do Item de Roteiro é feita a equivalência para Tipo de Demanda e Classificação.
B13: =ALI!B13 -> ¹ Em caso de cópia de Tipo de Demanda e/ou Classificação – colar o conteúdo em modo texto puro pois as células possuem fórmulas (menu “Editar” - “Colar Especial...” - “Texto”)
B14: =ALI!B14 -> Caso seja necessário transfira o conteúdo para a planilha do respectivo cliente. As planilhas podem ser obtidas na página do Escritório de Métricas:
B15: =ALI!B15 -> https://gitcorporativo.serpro/supde/SUPDE-EMPF/wikis/home
B17: Nome do EE | E17: AR | G17: Memória AR | I17: TD's | K17: Memória TD | M17: Tipo de Demanda ¹ | O17: Classificação | Y17: Compl | AE17: PF | AF17: PF Cheio | AK17: Rastreabilidade / Justificativa / Motivo-Comentário | AM17: Item de Roteiro – PONTUA | AN17: Marcadores de Grupo
M19: =IF(ISBLANK(AM19),'Item-Roteiro_PONTUA'!$B$20,VLOOKUP(AM19,'Item-Roteiro_PONTUA'!$A$2:$C$86,2,0)) -> Desenvolvimento | O19: =IF(ISBLANK(AM19),'Item-Roteiro_PONTUA'!$C$20,VLOOKUP(AM19,'Item-Roteiro_PONTUA'!$A$2:$C$86,3,0)) -> Incluída | AF19: =IF(Y19="Baixa",7,IF(Y19="Média",10,IF(Y19="Alta",15,"*"))) -> *
M20: =IF(ISBLANK(AM20),'Item-Roteiro_PONTUA'!$B$20,VLOOKUP(AM20,'Item-Roteiro_PONTUA'!$A$2:$C$86,2,0)) -> Desenvolvimento | O20: =IF(ISBLANK(AM20),'Item-Roteiro_PONTUA'!$C$20,VLOOKUP(AM20,'Item-Roteiro_PONTUA'!$A$2:$C$86,3,0)) -> Incluída
M21: =IF(ISBLANK(AM21),'Item-Roteiro_PONTUA'!$B$20,VLOOKUP(AM21,'Item-Roteiro_PONTUA'!$A$2:$C$86,2,0)) -> Desenvolvimento | O21: =IF(ISBLANK(AM21),'Item-Roteiro_PONTUA'!$C$20,VLOOKUP(AM21,'Item-Roteiro_PONTUA'!$A$2:$C$86,3,0)) -> Incluída
M22: =IF(ISBLANK(AM22),'Item-Roteiro_PONTUA'!$B$20,VLOOKUP(AM22,'Item-Roteiro_PONTUA'!$A$2:$C$86,2,0)) -> Desenvolvimento | O22: =IF(ISBLANK(AM22),'Item-Roteiro_PONTUA'!$C$20,VLOOKUP(AM22,'Item-Roteiro_PONTUA'!$A$2:$C$86,3,0)) -> Incluída
M23: =IF(ISBLANK(AM23),'Item-Roteiro_PONTUA'!$B$20,VLOOKUP(AM23,'Item-Roteiro_PONTUA'!$A$2:$C$86,2,0)) -> Desenvolvimento | O23: =IF(ISBLANK(AM23),'Item-Roteiro_PONTUA'!$C$20,VLOOKUP(AM23,'Item-Roteiro_PONTUA'!$A$2:$C$86,3,0)) -> Incluída
M24: =IF(ISBLANK(AM24),'Item-Roteiro_PONTUA'!$B$20,VLOOKUP(AM24,'Item-Roteiro_PONTUA'!$A$2:$C$86,2,0)) -> Desenvolvimento | O24: =IF(ISBLANK(AM24),'Item-Roteiro_PONTUA'!$C$20,VLOOKUP(AM24,'Item-Roteiro_PONTUA'!$A$2:$C$86,3,0)) -> Incluída
M25: =IF(ISBLANK(AM25),'Item-Roteiro_PONTUA'!$B$20,VLOOKUP(AM25,'Item-Roteiro_PONTUA'!$A$2:$C$86,2,0)) -> Desenvolvimento | O25: =IF(ISBLANK(AM25),'Item-Roteiro_PONTUA'!$C$20,VLOOKUP(AM25,'Item-Roteiro_PONTUA'!$A$2:$C$86,3,0)) -> Incluída
M26: =IF(ISBLANK(AM26),'Item-Roteiro_PONTUA'!$B$20,VLOOKUP(AM26,'Item-Roteiro_PONTUA'!$A$2:$C$86,2,0)) -> Desenvolvimento | O26: =IF(ISBLANK(AM26),'Item-Roteiro_PONTUA'!$C$20,VLOOKUP(AM26,'Item-Roteiro_PONTUA'!$A$2:$C$86,3,0)) -> Incluída
M27: =IF(ISBLANK(AM27),'Item-Roteiro_PONTUA'!$B$20,VLOOKUP(AM27,'Item-Roteiro_PONTUA'!$A$2:$C$86,2,0)) -> Desenvolvimento | O27: =IF(ISBLANK(AM27),'Item-Roteiro_PONTUA'!$C$20,VLOOKUP(AM27,'Item-Roteiro_PONTUA'!$A$2:$C$86,3,0)) -> Incluída
M28: =IF(ISBLANK(AM28),'Item-Roteiro_PONTUA'!$B$20,VLOOKUP(AM28,'Item-Roteiro_PONTUA'!$A$2:$C$86,2,0)) -> Desenvolvimento | O28: =IF(ISBLANK(AM28),'Item-Roteiro_PONTUA'!$C$20,VLOOKUP(AM28,'Item-Roteiro_PONTUA'!$A$2:$C$86,3,0)) -> Incluída
M29: =IF(ISBLANK(AM29),'Item-Roteiro_PONTUA'!$B$20,VLOOKUP(AM29,'Item-Roteiro_PONTUA'!$A$2:$C$86,2,0)) -> Desenvolvimento | O29: =IF(ISBLANK(AM29),'Item-Roteiro_PONTUA'!$C$20,VLOOKUP(AM29,'Item-Roteiro_PONTUA'!$A$2:$C$86,3,0)) -> Incluída
M30: =IF(ISBLANK(AM30),'Item-Roteiro_PONTUA'!$B$20,VLOOKUP(AM30,'Item-Roteiro_PONTUA'!$A$2:$C$86,2,0)) -> Desenvolvimento | O30: =IF(ISBLANK(AM30),'Item-Roteiro_PONTUA'!$C$20,VLOOKUP(AM30,'Item-Roteiro_PONTUA'!$A$2:$C$86,3,0)) -> Incluída
M31: =IF(ISBLANK(AM31),'Item-Roteiro_PONTUA'!$B$20,VLOOKUP(AM31,'Item-Roteiro_PONTUA'!$A$2:$C$86,2,0)) -> Desenvolvimento | O31: =IF(ISBLANK(AM31),'Item-Roteiro_PONTUA'!$C$20,VLOOKUP(AM31,'Item-Roteiro_PONTUA'!$A$2:$C$86,3,0)) -> Incluída
... M37: =IF(ISBLANK(AM37),'Item-Roteiro_PONTUA'!$B$20,VLOOKUP(AM37,'Item-Roteiro_PONTUA'!$A$2:$C$86,2,0)) -> Desenvolvimento | O37: =IF(ISBLANK(AM37),'Item-Roteiro_PONTUA'!$C$20,VLOOKUP(AM37,'Item-Roteiro_PONTUA'!$A$2:$C$86,3,0)) -> Incluída
M38: =IF(ISBLANK(AM38),'Item-Roteiro_PONTUA'!$B$20,VLOOKUP(AM38,'Item-Roteiro_PONTUA'!$A$2:$C$86,2,0)) -> Desenvolvimento | O38: =IF(ISBLANK(AM38),'Item-Roteiro_PONTUA'!$C$20,VLOOKUP(AM38,'Item-Roteiro_PONTUA'!$A$2:$C$86,3,0)) -> Incluída | AF38: =IF(Y38="Baixa",7,IF(Y38="Média",10,IF(Y38="Alta",15,"*"))) -> *
AF40: =SUM(AF19) -> 0
E41: Qtd de EE | I41: Total de PF
C42: Complexidade | E42: Transacional
C43: Baixa | E43: {=SUMPRODUCT((Y19:Y38=C43)*(LEFT(M19:M38,10)<>"Retrabalho"))} -> 0 | I43: {=SUMPRODUCT((Y19:Y38=C43)*(LEFT(M19:M38,10)<>"Retrabalho")*NOT(ISBLANK(AE19:AE38))*AE19:AE38)} -> 0
C44: Média | E44: {=SUMPRODUCT((Y19:Y38=C44)*(LEFT(M19:M38,10)<>"Retrabalho"))} -> 0 | I44: {=SUMPRODUCT((Y19:Y38=C44)*(LEFT(M19:M38,10)<>"Retrabalho")*NOT(ISBLANK(AE19:AE38))*AE19:AE38)} -> 0
C45: Alta | E45: {=SUMPRODUCT((Y19:Y38=C45)*(LEFT(M19:M38,10)<>"Retrabalho"))} -> 0 | I45: {=SUMPRODUCT((Y19:Y38=C45)*(LEFT(M19:M38,10)<>"Retrabalho")*NOT(ISBLANK(AE19:AE38))*AE19:AE38)} -> 0
E47: Retrabalho
C48: Baixa | E48: {=SUMPRODUCT((Y19:Y38=C48)*(LEFT(M19:M38,10)="Retrabalho"))} -> 0 | I48: {=SUMPRODUCT((Y19:Y38=C48)*(LEFT(M19:M38,10)="Retrabalho")*NOT(ISBLANK(AE19:AE38))*AE19:AE38)} -> 0
C49: Média | E49: {=SUMPRODUCT((Y19:Y38=C49)*(LEFT(M19:M38,10)="Retrabalho"))} -> 0 | I49: {=SUMPRODUCT((Y19:Y38=C49)*(LEFT(M19:M38,10)="Retrabalho")*NOT(ISBLANK(AE19:AE38))*AE19:AE38)} -> 0
C50: Alta | E50: {=SUMPRODUCT((Y19:Y38=C50)*(LEFT(M19:M38,10)="Retrabalho"))} -> 0 | I50: {=SUMPRODUCT((Y19:Y38=C50)*(LEFT(M19:M38,10)="Retrabalho")*NOT(ISBLANK(AE19:AE38))*AE19:AE38)} -> 0
E52: Total
C53: Baixa | E53: =E43+E48 -> 0 | I53: =I43+I48 -> 0
C54: Média | E54: =E44+E49 -> 0 | I54: =I44+I49 -> 0
C55: Alta | E55: =E45+E50 -> 0 | I55: =I45+I50 -> 0
E56: =E53+E54+E55 -> 0 | I56: =I53+I54+I55 -> 0
B59: PF Cheio desprezado nos Testes Não Func e Help | K59: =SUMPRODUCT((O19="Excluída")*AF19)+SUMPRODUCT((O19="Help")*AF19)+SUMPRODUCT((M19="Manutenção em Páginas Estáticas")*AF19)+SUMPRODUCT((M19="Manutenção em Interface")*AF19)+SUMPRODUCT((M19="Retrabalho Alteração de Interface")*AF19)+SUMPRODUCT((M19="Atualização de dados e PF de Domínio")*AF19)+SUMPRODUCT((M19="Testes Não Funcionais / Interoperabilidade")*AF19)+SUMPRODUCT((M19="Pontos de Função de Testes Funcionais")*AF19)+SUMPRODUCT((M19="Projeto de Automação de Testes")*AF19)+SUMPRODUCT((M19="Apuração Especial - Base de Dados – após consulta")*AF19)+SUMPRODUCT((M19="Apuração Especial - Base de Dados – sem consulta")*AF19) -> #VALUE!
B60: Povoamento de Homologação | K60: =SUMPRODUCT((O19="Massa de Dados")*AE19) -> 0
...

Sheet SE
B2: Identificação da Demanda: | E2: ${demanda.nome}
B9: Formulário de Identificação de Saídas Externas (SE)
B11: Orientações
B12: =ALI!B12 -> Evite editar os dados apresentados, cadastrar novas funcionalidades e/ou alterar seus dados. Esta planilha não realiza cálculos nas funções. Os dados da função foram exportados do Pontua, inclusive a Complexidade e o PF. O valor do PF foi calculado conforme Roteiro de Métricas informado na Contagem cadastrada na aplicação. Do Item de Roteiro é feita a equivalência para Tipo de Demanda e Classificação.
B13: =ALI!B13 -> ¹ Em caso de cópia de Tipo de Demanda e/ou Classificação – colar o conteúdo em modo texto puro pois as células possuem fórmulas (menu “Editar” - “Colar Especial...” - “Texto”)
B14: =ALI!B14 -> Caso seja necessário transfira o conteúdo para a planilha do respectivo cliente. As planilhas podem ser obtidas na página do Escritório de Métricas:
B15: =ALI!B15 -> https://gitcorporativo.serpro/supde/SUPDE-EMPF/wikis/home
B17: Nome do SE | E17: AR | G17: Memória AR | I17: TD's | K17: Memória TD | M17: Tipo de Demanda ¹ | O17: Classificação | Y17: Compl | AE17: PF | AF17: PF Cheio | AK17: Rastreabilidade / Justificativa / Motivo-Comentário | AM17: Item de Roteiro – PONTUA | AN17: Marcadores de Grupo
M19: =IF(ISBLANK(AM19),'Item-Roteiro_PONTUA'!$B$20,VLOOKUP(AM19,'Item-Roteiro_PONTUA'!$A$2:$C$86,2,0)) -> Desenvolvimento | O19: =IF(ISBLANK(AM19),'Item-Roteiro_PONTUA'!$C$20,VLOOKUP(AM19,'Item-Roteiro_PONTUA'!$A$2:$C$86,3,0)) -> Incluída | AF19: =IF(Y19="Baixa",7,IF(Y19="Média",10,IF(Y19="Alta",15,"*"))) -> *
M20: =IF(ISBLANK(AM20),'Item-Roteiro_PONTUA'!$B$20,VLOOKUP(AM20,'Item-Roteiro_PONTUA'!$A$2:$C$86,2,0)) -> Desenvolvimento | O20: =IF(ISBLANK(AM20),'Item-Roteiro_PONTUA'!$C$20,VLOOKUP(AM20,'Item-Roteiro_PONTUA'!$A$2:$C$86,3,0)) -> Incluída
M21: =IF(ISBLANK(AM21),'Item-Roteiro_PONTUA'!$B$20,VLOOKUP(AM21,'Item-Roteiro_PONTUA'!$A$2:$C$86,2,0)) -> Desenvolvimento | O21: =IF(ISBLANK(AM21),'Item-Roteiro_PONTUA'!$C$20,VLOOKUP(AM21,'Item-Roteiro_PONTUA'!$A$2:$C$86,3,0)) -> Incluída
M22: =IF(ISBLANK(AM22),'Item-Roteiro_PONTUA'!$B$20,VLOOKUP(AM22,'Item-Roteiro_PONTUA'!$A$2:$C$86,2,0)) -> Desenvolvimento | O22: =IF(ISBLANK(AM22),'Item-Roteiro_PONTUA'!$C$20,VLOOKUP(AM22,'Item-Roteiro_PONTUA'!$A$2:$C$86,3,0)) -> Incluída
M23: =IF(ISBLANK(AM23),'Item-Roteiro_PONTUA'!$B$20,VLOOKUP(AM23,'Item-Roteiro_PONTUA'!$A$2:$C$86,2,0)) -> Desenvolvimento | O23: =IF(ISBLANK(AM23),'Item-Roteiro_PONTUA'!$C$20,VLOOKUP(AM23,'Item-Roteiro_PONTUA'!$A$2:$C$86,3,0)) -> Incluída
M24: =IF(ISBLANK(AM24),'Item-Roteiro_PONTUA'!$B$20,VLOOKUP(AM24,'Item-Roteiro_PONTUA'!$A$2:$C$86,2,0)) -> Desenvolvimento | O24: =IF(ISBLANK(AM24),'Item-Roteiro_PONTUA'!$C$20,VLOOKUP(AM24,'Item-Roteiro_PONTUA'!$A$2:$C$86,3,0)) -> Incluída
M25: =IF(ISBLANK(AM25),'Item-Roteiro_PONTUA'!$B$20,VLOOKUP(AM25,'Item-Roteiro_PONTUA'!$A$2:$C$86,2,0)) -> Desenvolvimento | O25: =IF(ISBLANK(AM25),'Item-Roteiro_PONTUA'!$C$20,VLOOKUP(AM25,'Item-Roteiro_PONTUA'!$A$2:$C$86,3,0)) -> Incluída
M26: =IF(ISBLANK(AM26),'Item-Roteiro_PONTUA'!$B$20,VLOOKUP(AM26,'Item-Roteiro_PONTUA'!$A$2:$C$86,2,0)) -> Desenvolvimento | O26: =IF(ISBLANK(AM26),'Item-Roteiro_PONTUA'!$C$20,VLOOKUP(AM26,'Item-Roteiro_PONTUA'!$A$2:$C$86,3,0)) -> Incluída
M27: =IF(ISBLANK(AM27),'Item-Roteiro_PONTUA'!$B$20,VLOOKUP(AM27,'Item-Roteiro_PONTUA'!$A$2:$C$86,2,0)) -> Desenvolvimento | O27: =IF(ISBLANK(AM27),'Item-Roteiro_PONTUA'!$C$20,VLOOKUP(AM27,'Item-Roteiro_PONTUA'!$A$2:$C$86,3,0)) -> Incluída
M28: =IF(ISBLANK(AM28),'Item-Roteiro_PONTUA'!$B$20,VLOOKUP(AM28,'Item-Roteiro_PONTUA'!$A$2:$C$86,2,0)) -> Desenvolvimento | O28: =IF(ISBLANK(AM28),'Item-Roteiro_PONTUA'!$C$20,VLOOKUP(AM28,'Item-Roteiro_PONTUA'!$A$2:$C$86,3,0)) -> Incluída
M29: =IF(ISBLANK(AM29),'Item-Roteiro_PONTUA'!$B$20,VLOOKUP(AM29,'Item-Roteiro_PONTUA'!$A$2:$C$86,2,0)) -> Desenvolvimento | O29: =IF(ISBLANK(AM29),'Item-Roteiro_PONTUA'!$C$20,VLOOKUP(AM29,'Item-Roteiro_PONTUA'!$A$2:$C$86,3,0)) -> Incluída
M30: =IF(ISBLANK(AM30),'Item-Roteiro_PONTUA'!$B$20,VLOOKUP(AM30,'Item-Roteiro_PONTUA'!$A$2:$C$86,2,0)) -> Desenvolvimento | O30: =IF(ISBLANK(AM30),'Item-Roteiro_PONTUA'!$C$20,VLOOKUP(AM30,'Item-Roteiro_PONTUA'!$A$2:$C$86,3,0)) -> Incluída
M31: =IF(ISBLANK(AM31),'Item-Roteiro_PONTUA'!$B$20,VLOOKUP(AM31,'Item-Roteiro_PONTUA'!$A$2:$C$86,2,0)) -> Desenvolvimento | O31: =IF(ISBLANK(AM31),'Item-Roteiro_PONTUA'!$C$20,VLOOKUP(AM31,'Item-Roteiro_PONTUA'!$A$2:$C$86,3,0)) -> Incluída
... M37: =IF(ISBLANK(AM37),'Item-Roteiro_PONTUA'!$B$20,VLOOKUP(AM37,'Item-Roteiro_PONTUA'!$A$2:$C$86,2,0)) -> Desenvolvimento | O37: =IF(ISBLANK(AM37),'Item-Roteiro_PONTUA'!$C$20,VLOOKUP(AM37,'Item-Roteiro_PONTUA'!$A$2:$C$86,3,0)) -> Incluída
M38: =IF(ISBLANK(AM38),'Item-Roteiro_PONTUA'!$B$20,VLOOKUP(AM38,'Item-Roteiro_PONTUA'!$A$2:$C$86,2,0)) -> Desenvolvimento | O38: =IF(ISBLANK(AM38),'Item-Roteiro_PONTUA'!$C$20,VLOOKUP(AM38,'Item-Roteiro_PONTUA'!$A$2:$C$86,3,0)) -> Incluída | AF38: =IF(Y38="Baixa",7,IF(Y38="Média",10,IF(Y38="Alta",15,"*"))) -> *
AF40: =SUM(AF19) -> 0
E41: Qtd de SE | I41: Total de PF
C42: Complexidade | E42: Transacional
C43: Baixa | E43: {=SUMPRODUCT((Y19:Y38=C43)*(LEFT(M19:M38,10)<>"Retrabalho"))} -> 0 | I43: {=SUMPRODUCT((Y19:Y38=C43)*(LEFT(M19:M38,10)<>"Retrabalho")*NOT(ISBLANK(AE19:AE38))*AE19:AE38)} -> 0
C44: Média | E44: {=SUMPRODUCT((Y19:Y38=C44)*(LEFT(M19:M38,10)<>"Retrabalho"))} -> 0 | I44: {=SUMPRODUCT((Y19:Y38=C44)*(LEFT(M19:M38,10)<>"Retrabalho")*NOT(ISBLANK(AE19:AE38))*AE19:AE38)} -> 0
C45: Alta | E45: {=SUMPRODUCT((Y19:Y38=C45)*(LEFT(M19:M38,10)<>"Retrabalho"))} -> 0 | I45: {=SUMPRODUCT((Y19:Y38=C45)*(LEFT(M19:M38,10)<>"Retrabalho")*NOT(ISBLANK(AE19:AE38))*AE19:AE38)} -> 0
E47: Retrabalho
C48: Baixa | E48: {=SUMPRODUCT((Y19:Y38=C48)*(LEFT(M19:M38,10)="Retrabalho"))} -> 0 | I48: {=SUMPRODUCT((Y19:Y38=C48)*(LEFT(M19:M38,10)="Retrabalho")*NOT(ISBLANK(AE19:AE38))*AE19:AE38)} -> 0
C49: Média | E49: {=SUMPRODUCT((Y19:Y38=C49)*(LEFT(M19:M38,10)="Retrabalho"))} -> 0 | I49: {=SUMPRODUCT((Y19:Y38=C49)*(LEFT(M19:M38,10)="Retrabalho")*NOT(ISBLANK(AE19:AE38))*AE19:AE38)} -> 0
C50: Alta | E50: {=SUMPRODUCT((Y19:Y38=C50)*(LEFT(M19:M38,10)="Retrabalho"))} -> 0 | I50: {=SUMPRODUCT((Y19:Y38=C50)*(LEFT(M19:M38,10)="Retrabalho")*NOT(ISBLANK(AE19:AE38))*AE19:AE38)} -> 0
E52: Total
C53: Baixa | E53: =E43+E48 -> 0 | I53: =I43+I48 -> 0
C54: Média | E54: =E44+E49 -> 0 | I54: =I44+I49 -> 0
C55: Alta | E55: =E45+E50 -> 0 | I55: =I45+I50 -> 0
E56: =E53+E54+E55 -> 0 | I56: =I53+I54+I55 -> 0
B59: PF Cheio desprezado nos Testes Não Func e Help | K59: =SUMPRODUCT((O19="Excluída")*AF19)+SUMPRODUCT((O19="Help")*AF19)+SUMPRODUCT((M19="Manutenção em Páginas Estáticas")*AF19)+SUMPRODUCT((M19="Manutenção em Interface")*AF19)+SUMPRODUCT((M19="Retrabalho Alteração de Interface")*AF19)+SUMPRODUCT((M19="Atualização de dados e PF de Domínio")*AF19)+SUMPRODUCT((M19="Testes Não Funcionais / Interoperabilidade")*AF19)+SUMPRODUCT((M19="Pontos de Função de Testes Funcionais")*AF19)+SUMPRODUCT((M19="Projeto de Automação de Testes")*AF19)+SUMPRODUCT((M19="Apuração Especial - Base de Dados – após consulta")*AF19)+SUMPRODUCT((M19="Apuração Especial - Base de Dados – sem consulta")*AF19) -> #VALUE!
B60: PF Deflacionado desprezado no GRS | K60: =SUMPRODUCT((O19="Excluída")*AE19)+SUMPRODUCT((O19="Help")*AE19)+SUMPRODUCT((M19="Manutenção em Páginas Estáticas")*AE19)+SUMPRODUCT((M19="Manutenção em Interface")*AE19)+SUMPRODUCT((M19="Retrabalho Alteração de Interface")*AE19)+SUMPRODUCT((M19="Atualização de dados e PF de Domínio")*AE19)+SUMPRODUCT((M19="Testes Não Funcionais / Interoperabilidade")*AE19)+SUMPRODUCT((M19="Pontos de Função de Testes Funcionais")*AE19)+SUMPRODUCT((M19="Projeto de Automação de Testes")*AE19)+SUMPRODUCT((M19="Apuração Especial - Base de Dados – após consulta")*AE19)+SUMPRODUCT((M19="Apuração Especial - Base de Dados – sem consulta")*AE19) -> 0

Sheet CE
B2: Identificação da Demanda: | E2: ${demanda.nome}
B9: Formulário de Identificação de Consultas Externas (CE)
B11: Orientações
B12: =ALI!B12 -> Evite editar os dados apresentados, cadastrar novas funcionalidades e/ou alterar seus dados. Esta planilha não realiza cálculos nas funções. Os dados da função foram exportados do Pontua, inclusive a Complexidade e o PF. O valor do PF foi calculado conforme Roteiro de Métricas informado na Contagem cadastrada na aplicação. Do Item de Roteiro é feita a equivalência para Tipo de Demanda e Classificação.
B13: =ALI!B13 -> ¹ Em caso de cópia de Tipo de Demanda e/ou Classificação – colar o conteúdo em modo texto puro pois as células possuem fórmulas (menu “Editar” - “Colar Especial...” - “Texto”)
B14: =ALI!B14 -> Caso seja necessário transfira o conteúdo para a planilha do respectivo cliente. As planilhas podem ser obtidas na página do Escritório de Métricas:
B15: =ALI!B15 -> https://gitcorporativo.serpro/supde/SUPDE-EMPF/wikis/home
B17: Nome do CE | E17: AR | G17: Memória AR | I17: TD's | K17: Memória TD | M17: Tipo de Demanda ¹ | O17: Classificação | Y17: Compl | AE17: PF | AF17: PF Cheio | AK17: Rastreabilidade / Justificativa / Motivo-Comentário | AM17: Item de Roteiro – PONTUA | AN17: Marcadores de Grupo
M19: =IF(ISBLANK(AM19),'Item-Roteiro_PONTUA'!$B$20,VLOOKUP(AM19,'Item-Roteiro_PONTUA'!$A$2:$C$86,2,0)) -> Desenvolvimento | O19: =IF(ISBLANK(AM19),'Item-Roteiro_PONTUA'!$C$20,VLOOKUP(AM19,'Item-Roteiro_PONTUA'!$A$2:$C$86,3,0)) -> Incluída | AF19: =IF(Y19="Baixa",7,IF(Y19="Média",10,IF(Y19="Alta",15,"*"))) -> *
M20: =IF(ISBLANK(AM20),'Item-Roteiro_PONTUA'!$B$20,VLOOKUP(AM20,'Item-Roteiro_PONTUA'!$A$2:$C$86,2,0)) -> Desenvolvimento | O20: =IF(ISBLANK(AM20),'Item-Roteiro_PONTUA'!$C$20,VLOOKUP(AM20,'Item-Roteiro_PONTUA'!$A$2:$C$86,3,0)) -> Incluída
M21: =IF(ISBLANK(AM21),'Item-Roteiro_PONTUA'!$B$20,VLOOKUP(AM21,'Item-Roteiro_PONTUA'!$A$2:$C$86,2,0)) -> Desenvolvimento | O21: =IF(ISBLANK(AM21),'Item-Roteiro_PONTUA'!$C$20,VLOOKUP(AM21,'Item-Roteiro_PONTUA'!$A$2:$C$86,3,0)) -> Incluída
M22: =IF(ISBLANK(AM22),'Item-Roteiro_PONTUA'!$B$20,VLOOKUP(AM22,'Item-Roteiro_PONTUA'!$A$2:$C$86,2,0)) -> Desenvolvimento | O22: =IF(ISBLANK(AM22),'Item-Roteiro_PONTUA'!$C$20,VLOOKUP(AM22,'Item-Roteiro_PONTUA'!$A$2:$C$86,3,0)) -> Incluída
M23: =IF(ISBLANK(AM23),'Item-Roteiro_PONTUA'!$B$20,VLOOKUP(AM23,'Item-Roteiro_PONTUA'!$A$2:$C$86,2,0)) -> Desenvolvimento | O23: =IF(ISBLANK(AM23),'Item-Roteiro_PONTUA'!$C$20,VLOOKUP(AM23,'Item-Roteiro_PONTUA'!$A$2:$C$86,3,0)) -> Incluída
M24: =IF(ISBLANK(AM24),'Item-Roteiro_PONTUA'!$B$20,VLOOKUP(AM24,'Item-Roteiro_PONTUA'!$A$2:$C$86,2,0)) -> Desenvolvimento | O24: =IF(ISBLANK(AM24),'Item-Roteiro_PONTUA'!$C$20,VLOOKUP(AM24,'Item-Roteiro_PONTUA'!$A$2:$C$86,3,0)) -> Incluída
M25: =IF(ISBLANK(AM25),'Item-Roteiro_PONTUA'!$B$20,VLOOKUP(AM25,'Item-Roteiro_PONTUA'!$A$2:$C$86,2,0)) -> Desenvolvimento | O25: =IF(ISBLANK(AM25),'Item-Roteiro_PONTUA'!$C$20,VLOOKUP(AM25,'Item-Roteiro_PONTUA'!$A$2:$C$86,3,0)) -> Incluída
M26: =IF(ISBLANK(AM26),'Item-Roteiro_PONTUA'!$B$20,VLOOKUP(AM26,'Item-Roteiro_PONTUA'!$A$2:$C$86,2,0)) -> Desenvolvimento | O26: =IF(ISBLANK(AM26),'Item-Roteiro_PONTUA'!$C$20,VLOOKUP(AM26,'Item-Roteiro_PONTUA'!$A$2:$C$86,3,0)) -> Incluída
M27: =IF(ISBLANK(AM27),'Item-Roteiro_PONTUA'!$B$20,VLOOKUP(AM27,'Item-Roteiro_PONTUA'!$A$2:$C$86,2,0)) -> Desenvolvimento | O27: =IF(ISBLANK(AM27),'Item-Roteiro_PONTUA'!$C$20,VLOOKUP(AM27,'Item-Roteiro_PONTUA'!$A$2:$C$86,3,0)) -> Incluída
M28: =IF(ISBLANK(AM28),'Item-Roteiro_PONTUA'!$B$20,VLOOKUP(AM28,'Item-Roteiro_PONTUA'!$A$2:$C$86,2,0)) -> Desenvolvimento | O28: =IF(ISBLANK(AM28),'Item-Roteiro_PONTUA'!$C$20,VLOOKUP(AM28,'Item-Roteiro_PONTUA'!$A$2:$C$86,3,0)) -> Incluída
M29: =IF(ISBLANK(AM29),'Item-Roteiro_PONTUA'!$B$20,VLOOKUP(AM29,'Item-Roteiro_PONTUA'!$A$2:$C$86,2,0)) -> Desenvolvimento | O29: =IF(ISBLANK(AM29),'Item-Roteiro_PONTUA'!$C$20,VLOOKUP(AM29,'Item-Roteiro_PONTUA'!$A$2:$C$86,3,0)) -> Incluída
M30: =IF(ISBLANK(AM30),'Item-Roteiro_PONTUA'!$B$20,VLOOKUP(AM30,'Item-Roteiro_PONTUA'!$A$2:$C$86,2,0)) -> Desenvolvimento | O30: =IF(ISBLANK(AM30),'Item-Roteiro_PONTUA'!$C$20,VLOOKUP(AM30,'Item-Roteiro_PONTUA'!$A$2:$C$86,3,0)) -> Incluída
M31: =IF(ISBLANK(AM31),'Item-Roteiro_PONTUA'!$B$20,VLOOKUP(AM31,'Item-Roteiro_PONTUA'!$A$2:$C$86,2,0)) -> Desenvolvimento | O31: =IF(ISBLANK(AM31),'Item-Roteiro_PONTUA'!$C$20,VLOOKUP(AM31,'Item-Roteiro_PONTUA'!$A$2:$C$86,3,0)) -> Incluída
... M37: =IF(ISBLANK(AM37),'Item-Roteiro_PONTUA'!$B$20,VLOOKUP(AM37,'Item-Roteiro_PONTUA'!$A$2:$C$86,2,0)) -> Desenvolvimento | O37: =IF(ISBLANK(AM37),'Item-Roteiro_PONTUA'!$C$20,VLOOKUP(AM37,'Item-Roteiro_PONTUA'!$A$2:$C$86,3,0)) -> Incluída
M38: =IF(ISBLANK(AM38),'Item-Roteiro_PONTUA'!$B$20,VLOOKUP(AM38,'Item-Roteiro_PONTUA'!$A$2:$C$86,2,0)) -> Desenvolvimento | O38: =IF(ISBLANK(AM38),'Item-Roteiro_PONTUA'!$C$20,VLOOKUP(AM38,'Item-Roteiro_PONTUA'!$A$2:$C$86,3,0)) -> Incluída | AF38: =IF(Y38="Baixa",7,IF(Y38="Média",10,IF(Y38="Alta",15,"*"))) -> *
AF40: =SUM(AF19) -> 0
E41: Qtd de CE | I41: Total de PF
C42: Complexidade | E42: Transacional
C43: Baixa | E43: {=SUMPRODUCT((Y19:Y38=C43)*(LEFT(M19:M38,10)<>"Retrabalho"))} -> 0 | I43: {=SUMPRODUCT((Y19:Y38=C43)*(LEFT(M19:M38,10)<>"Retrabalho")*NOT(ISBLANK(AE19:AE38))*AE19:AE38)} -> 0
C44: Média | E44: {=SUMPRODUCT((Y19:Y38=C44)*(LEFT(M19:M38,10)<>"Retrabalho"))} -> 0 | I44: {=SUMPRODUCT((Y19:Y38=C44)*(LEFT(M19:M38,10)<>"Retrabalho")*NOT(ISBLANK(AE19:AE38))*AE19:AE38)} -> 0
C45: Alta | E45: {=SUMPRODUCT((Y19:Y38=C45)*(LEFT(M19:M38,10)<>"Retrabalho"))} -> 0 | I45: {=SUMPRODUCT((Y19:Y38=C45)*(LEFT(M19:M38,10)<>"Retrabalho")*NOT(ISBLANK(AE19:AE38))*AE19:AE38)} -> 0
E47: Retrabalho
C48: Baixa | E48: {=SUMPRODUCT((Y19:Y38=C48)*(LEFT(M19:M38,10)="Retrabalho"))} -> 0 | I48: {=SUMPRODUCT((Y19:Y38=C48)*(LEFT(M19:M38,10)="Retrabalho")*NOT(ISBLANK(AE19:AE38))*AE19:AE38)} -> 0
C49: Média | E49: {=SUMPRODUCT((Y19:Y38=C49)*(LEFT(M19:M38,10)="Retrabalho"))} -> 0 | I49: {=SUMPRODUCT((Y19:Y38=C49)*(LEFT(M19:M38,10)="Retrabalho")*NOT(ISBLANK(AE19:AE38))*AE19:AE38)} -> 0
C50: Alta | E50: {=SUMPRODUCT((Y19:Y38=C50)*(LEFT(M19:M38,10)="Retrabalho"))} -> 0 | I50: {=SUMPRODUCT((Y19:Y38=C50)*(LEFT(M19:M38,10)="Retrabalho")*NOT(ISBLANK(AE19:AE38))*AE19:AE38)} -> 0
E52: Total
C53: Baixa | E53: =E43+E48 -> 0 | I53: =I43+I48 -> 0
C54: Média | E54: =E44+E49 -> 0 | I54: =I44+I49 -> 0
C55: Alta | E55: =E45+E50 -> 0 | I55: =I45+I50 -> 0
E56: =E53+E54+E55 -> 0 | I56: =I53+I54+I55 -> 0
B59: PF Cheio desprezado nos Testes Não Func e Help | K59: =SUMPRODUCT((O19="Excluída")*AF19)+SUMPRODUCT((O19="Help")*AF19)+SUMPRODUCT((M19="Manutenção em Páginas Estáticas")*AF19)+SUMPRODUCT((M19="Manutenção em Interface")*AF19)+SUMPRODUCT((M19="Retrabalho Alteração de Interface")*AF19)+SUMPRODUCT((M19="Atualização de dados e PF de Domínio")*AF19)+SUMPRODUCT((M19="Testes Não Funcionais / Interoperabilidade")*AF19)+SUMPRODUCT((M19="Pontos de Função de Testes Funcionais")*AF19)+SUMPRODUCT((M19="Projeto de Automação de Testes")*AF19)+SUMPRODUCT((M19="Apuração Especial - Base de Dados – após consulta")*AF19)+SUMPRODUCT((M19="Apuração Especial - Base de Dados – sem consulta")*AF19) -> #VALUE!
B60: PF Deflacionado desprezado no GRS | K60: =SUMPRODUCT((O19="Excluída")*AE19)+SUMPRODUCT((O19="Help")*AE19)+SUMPRODUCT((M19="Manutenção em Páginas Estáticas")*AE19)+SUMPRODUCT((M19="Manutenção em Interface")*AE19)+SUMPRODUCT((M19="Retrabalho Alteração de Interface")*AE19)+SUMPRODUCT((M19="Atualização de dados e PF de Domínio")*AE19)+SUMPRODUCT((M19="Testes Não Funcionais / Interoperabilidade")*AE19)+SUMPRODUCT((M19="Pontos de Função de Testes Funcionais")*AE19)+SUMPRODUCT((M19="Projeto de Automação de Testes")*AE19)+SUMPRODUCT((M19="Apuração Especial - Base de Dados – após consulta")*AE19)+SUMPRODUCT((M19="Apuração Especial - Base de Dados – sem consulta")*AE19) -> 0

Sheet Atividades sem contagem de PF

Sheet Item-Roteiro_PONTUA
A1: ITEM DE ROTEIRO - PONTUA | B1: EQUIVALÊNCIA - Tipo de Demanda | C1: EQUIVALÊNCIA - Classificação
A2: AESP - BD - Pós Consulta | B2: Apuração Especial - Base de Dados – após consulta | C2: Incluída
A3: AESP - BD - Sem Consulta | B3: Apuração Especial - Base de Dados – sem consulta | C3: Incluída
A4: AESP - BD - Somente Consulta ou Consulta Prévia | B4: Apuração Especial - Base de Dados – somente consulta | C4: Incluída
A5: AESP - Execução - Alteração de Parâmetros | C5: Incluída
A6: AESP - Geração de Relatórios | B6: Apuração Especial - Geração de Relatórios | C6: Incluída
A7: AESP - Reexecução | B7: Apuração Especial – Reexecução | C7: Incluída
A8: Atualização de Dados / Domínio | B8: Atualização de dados e PF de Domínio | C8: Incluída
A9: Atualização de Versão - BD | B9: Atualização de Plataforma – Banco de Dados | C9: Alterada
A10: Atualização de Versão - Browser | B10: Atualização de Plataforma – Browser | C10: Alterada
A11: Atualização de Versão - LP | B11: Atualização de Plataforma – Linguagem de Programação | C11: Alterada
A12: Atualização de Versão - Sistema Operacional | B12: Atualização de Plataforma – Sistema Operacional | C12: Alterada
A13: Componente - Alterada - Arquivo Configuração | B13: Componente Interno Reusável | C13: Alterada
A14: Componente - Alterada - Sistema Empresa | B14: Componente Interno Reusável | C14: Alterada
A15: Componente - Alterada - Sistema Outros - Com Redoc. | B15: Componente Interno Reusável | C15: Alterada
A16: Componente - Alterada - Sistema Outros - Sem Redoc. | B16: Componente Interno Reusável | C16: Alterada
A17: Componente - Excluída | B17: Componente Interno Reusável | C17: Excluída
... A37: Manutenção de Interface - Incluída | B37: Manutenção em Interface | C37: Incluída
A38: Massa de Dados | C38: Massa de Dados
A39: Massa de Dados - Manutenção Corretiva | B39: Manutenção Corretiva | C39: Massa de Dados
A40: Help | C40: Help
A41: Melhoria - Alterada - Sistema Empresa | B41: Melhoria | C41: Alterada
A42: Melhoria - Alterada - Sistema Outros - Com Redoc. | B42: Melhoria | C42: Alterada
A43: Melhoria - Alterada - Sistema Outros - Sem Redoc. | B43: Melhoria | C43: Alterada
A44: Melhoria - Conversão | B44: Melhoria | C44: Conversão
A45: Melhoria - Excluída | B45: Melhoria | C45: Excluída
A46: Melhoria - Incluída | B46: Melhoria | C46: Incluída
A47: Migração | B47: Migração de Dados | C47: Incluída
A48: Retrabalho Alteração de Interface - Fase Design, Arquitetura | B48: Retrabalho Alteração de Interface | C48: Fase Design, Arquitetura
A49: Retrabalho Alteração de Interface - Fase Engenharia de Requisitos | B49: Retrabalho Alteração de Interface | C49: Fase Engenharia de Requisitos
A50: Retrabalho Alteração de Interface - Fase Homologação | B50: Retrabalho Alteração de Interface | C50: Fase Homologação
A51: Retrabalho Alteração de Interface - Fase Implementação | B51: Retrabalho Alteração de Interface | C51: Fase Implementação
A52: Retrabalho Alteração de Interface - Fase Testes | B52: Retrabalho Alteração de Interface | C52: Fase Testes
... A86: Verificação de Erros - sem Documentação de Testes | B86: Verificação de Erros | C86: Incluída

Sheet Validar
A1: Roteiro Serpro | B1: V7.6 | C1: . | D1: Plataforma | G1: CLASSIFICAÇÃO | I1: Tipo | J1: Fator Serpro | K1: Fator RFB | L1: Forma de Cálculo | M1: Funcionalidades
D2: UNIX | G2: Incluída | I2: Desenvolvimento - Incluída | J2: 1 | K2: 1 | L2: P | M2: ALI | N2: AIE | O2: EE | P2: SE | Q2: CE
A3: CPM | B3: v4.3.1 | D3: Grande Porte | G3: Alterada | I3: Desenvolvimento - Conversão | J3: 1 | K3: 1 | L3: P | N3: AIE | O3: EE | P3: SE | Q3: CE
D4: WEB | G4: Excluída | I4: Melhoria - Incluída | J4: 1 | K4: 1 | L4: P | M4: ALI | N4: AIE | O4: EE | P4: SE | Q4: CE
A5: Linguagem | D5: WINDOWS | G5: Conversão | I5: Melhoria - Alterada | J5: 0.75 | K5: 0.75 | L5: P | M5: ALI | N5: AIE | O5: EE | P5: SE | Q5: CE
A6: ACCESS | D6: LINUX | G6: Help | I6: Melhoria - Excluída | J6: 0.4 | K6: 0.4 | L6: P | M6: ALI | N6: AIE | O6: EE | P6: SE | Q6: CE
A7: ASP | G7: Fase Engenharia de Requisitos | I7: Melhoria - Conversão | J7: 1 | K7: 1 | L7: P | N7: AIE | O7: EE | P7: SE | Q7: CE
A8: ASPNET | D8: Tipo de Contagem | G8: Fase Design, Arquitetura | I8: Migração de Dados - Incluída | J8: 1 | K8: 1 | L8: P | M8: ALI | N8: AIE | O8: EE | P8: SE
A9: ASSEMBLER | D9: Estimativa Inicial | G9: Fase Implementação | I9: Migração de Dados - Conversão | J9: 1 | K9: 1 | L9: P | M9: ALI | N9: AIE | O9: EE | P9: SE | Q9: CE
A10: BASIC | D10: Contagem de Referência | G10: Fase Testes | I10: Manutenção Corretiva - Alterada | J10: 0.75 | K10: 0.75 | L10: P | M10: ALI | N10: AIE | O10: EE | P10: SE | Q10: CE
A11: C | D11: Contagem de Encerramento | G11: Fase Homologação | I11: Redesenvolvimento em outra plataforma – Linguagem de Programação - Incluída | J11: 1 | K11: 1 | L11: P | M11: ALI | N11: AIE | O11: EE | P11: SE | Q11: CE
A12: C# | G12: Fase Implantação | I12: Redesenvolvimento em outra plataforma – Linguagem de Programação - Conversão | J12: 1 | K12: 1 | L12: P | N12: AIE | O12: EE | P12: SE | Q12: CE
A13: C++ | D13: Redução de Cronograma | E13: % | G13: Massa de Dados | I13: Redesenvolvimento em outra plataforma – Banco de Dados Hierárquico - Incluída | J13: 1 | K13: 1 | L13: P | M13: ALI | N13: AIE | O13: EE | P13: SE | Q13: CE
A14: CKAN | D14: Não | E14: 0 | I14: Redesenvolvimento em outra plataforma – Banco de Dados Hierárquico - Conversão | J14: 1 | K14: 1 | L14: P | N14: AIE | O14: EE | P14: SE | Q14: CE
A15: CLIPPER | D15: Projeto Urgente | E15: 0.2 | I15: Redesenvolvimento em outra plataforma – Banco de Dados Relacional - Alterada | J15: 0.5 | K15: 0.5 | L15: P | M15: ALI | N15: AIE | O15: EE | P15: SE | Q15: CE
A16: COBOL | D16: Projeto Crítico | E16: 0.5 | G16: Tipos de demanda | I16: Redesenvolvimento em outra plataforma – Banco de Dados Relacional - Conversão | J16: 1 | K16: 1 | L16: P | N16: AIE | O16: EE | P16: SE | Q16: CE
A17: CSP | D17: Projeto Alta Criticidade | E17: 0.7 | G17: Desenvolvimento | I17: Atualização de Plataforma – Linguagem de Programação - Alterada | J17: 0.3 | K17: 0.3 | L17: P | O17: EE | P17: SE | Q17: CE
A18: Dardo /Netuno | G18: Melhoria | I18: Atualização de Plataforma – Browser - Alterada | J18: 0.3 | K18: 0.3 | L18: P | O18: EE | P18: SE | Q18: CE
A19: DATA DISCOVERY | D19: Versão / autor | E19: Data | G19: Migração de Dados | I19: Atualização de Plataforma – Banco de Dados - Alterada | J19: 0.3 | K19: 0.3 | L19: P | O19: EE | P19: SE | Q19: CE
A20: DELPHI | D20: 36 – Edilson (correção do cálculo de Help nas abas Serpro e Sumário que devem incidir sobre PF Cheio) | E20: 42905 | G20: Manutenção Corretiva | I20: Manutenção em Interface - Alterada | J20: 0.6 | K20: 0.6 | L20: F | O20: EE | P20: SE | Q20: CE
A21: Dot Net (.Net) | D21: 35 – Luciano Buzzacaro (Inclusão do 'Componente Interno Reusável – Excluída' linha i88) | E21: 42668 | G21: Redesenvolvimento em outra plataforma – Linguagem de Programação | I21: Manutenção em Interface - Help | J21: 0.6 | K21: 0.6 | L21: F | O21: EE | P21: SE | Q21: CE
A22: EXCEL | D22: 34 – Edilson Eloy | E22: 42415 | G22: Redesenvolvimento em outra plataforma – Banco de Dados Hierárquico | I22: Manutenção Adaptativa em Requisitos Não Funcionais / Preventiva - Alterada | J22: 0.75 | K22: 0.75 | L22: P | M22: ALI | N22: AIE | O22: EE | P22: SE | Q22: CE
A23: FORMS/REPORTS/ORACLE | G23: Redesenvolvimento em outra plataforma – Banco de Dados Relacional | I23: Apuração Especial - Base de Dados – sem consulta - Incluída | J23: 1 | K23: 1 | L23: P | O23: EE
A24: HTML | D24: Versão | G24: Atualização de Plataforma – Linguagem de Programação | I24: Apuração Especial - Base de Dados – somente consulta - Incluída | J24: 1 | K24: 1 | L24: P | P24: SE | Q24: CE
A25: JAVA | D25: v36 | G25: Atualização de Plataforma – Browser | I25: Apuração Especial - Base de Dados – após consulta - Incluída | J25: 0.6 | K25: 0.6 | L25: P | O25: EE
A26: Java AndroMDA | G26: Atualização de Plataforma – Banco de Dados | I26: Apuração Especial - Geração de Relatórios - Incluída | J26: 1 | K26: 1 | L26: P | P26: SE | Q26: CE
A27: Java Demoiselle V 1.0 | D27: Processo | G27: Manutenção em Interface | I27: Apuração Especial – Reexecução - Incluída | J27: 0.1 | K27: 0.1 | L27: P | O27: EE | P27: SE | Q27: CE
A28: Java Demoiselle V 2.0 | D28: Sumário | G28: Manutenção Adaptativa em Requisitos Não Funcionais / Preventiva | I28: Apuração Especial – Reexecução - Alterada | J28: 0.1 | K28: 0.1 | L28: P
A29: Java Flex | D29: Completo | G29: Apuração Especial - Base de Dados – sem consulta | I29: Atualização de dados e PF de Domínio - Incluída | J29: 0.1 | K29: 0.1 | L29: P | O29: EE
A30: Java Script | D30: Expresso | G30: Apuração Especial - Base de Dados – somente consulta | I30: Manutenção em Páginas Estáticas - Incluída | J30: 0.6 | K30: 0.6 | L30: F | Q30: CE
A31: Java Web | D31: Ágil | G31: Apuração Especial - Base de Dados – após consulta | I31: Manutenção em Páginas Estáticas - Alterada | J31: 0.6 | K31: 0.6 | L31: F | Q31: CE
A32: JCUPIM | G32: Apuração Especial - Geração de Relatórios | I32: Manutenção de Documentação de Sistemas Legados - Incluída | J32: 0.25 | K32: 0.25 | L32: P | M32: ALI | N32: AIE | O32: EE | P32: SE | Q32: CE
A33: JOOMLA | D33: Processo | G33: Apuração Especial – Reexecução | I33: Manutenção de Documentação de Sistemas Legados - Alterada | J33: 0.25 | K33: 0.25 | L33: P | M33: ALI | N33: AIE | O33: EE | P33: SE | Q33: CE
A34: LASER XEROX | D34: Desenvolvimento | G34: Atualização de dados e PF de Domínio | I34: Verificação de Erros - Incluída | J34: 0.2 | K34: 0.2 | L34: P | M34: ALI | N34: AIE | O34: EE | P34: SE | Q34: CE
A35: LIFERAY | D35: Manutenção Adaptativa | G35: Manutenção em Páginas Estáticas | I35: Verificação de Erros - Alterada | J35: 0.2 | K35: 0.2 | L35: P | M35: ALI | N35: AIE | O35: EE | P35: SE | Q35: CE
A36: LIGHTBASE | D36: Manutenção Evolutiva | G36: Manutenção de Documentação de Sistemas Legados | I36: Testes Não Funcionais / Interoperabilidade - Incluída | J36: 0.25 | K36: 0.25 | L36: P | O36: EE | P36: SE | Q36: CE
A37: LOTUS NOTES | D37: Manutenção Corretiva | G37: Verificação de Erros | I37: Testes Não Funcionais / Interoperabilidade - Alterada | J37: 0.25 | K37: 0.25 | L37: P | O37: EE | P37: SE | Q37: CE
A38: LTD | D38: Apuração Especial | G38: Testes Não Funcionais / Interoperabilidade | I38: Pontos de Função de Testes Funcionais - Incluída | J38: 0.15 | K38: 0.15 | L38: P | O38: EE | P38: SE | Q38: CE
A39: MIDDLEWARE | G39: Pontos de Função de Testes Funcionais | I39: Componente Interno Reusável - Incluída | J39: 1 | K39: 1 | L39: P | O39: EE | P39: SE | Q39: CE
A40: MOBILE - ANDROID | D40: Sim | G40: Componente Interno Reusável | I40: Componente Interno Reusável - Alterada | J40: 1 | K40: 1 | L40: P | O40: EE | P40: SE | Q40: CE
...
